Workbook

Sheet 每月汇总
A1: 华尔特工业园光伏项目发电2026年1月统计表
A2: 用户号 | B2: 发电表号 | C2: 发电表资产编号 | D2: 上网表号 | E2: 上网表资产号 | F2: 发电量 | G2: 上网电量 | H2: 实际用电数 | I2: 金额 | J2: 上网费
A3: ='202601'!Q3 -> 0948030027271605 | B3: ='202601'!Q4 -> 0948030044326050 | C3: ='202601'!Q5 -> 09001SF00000042508942176 | D3: ='202601'!Q6 -> 0948030027271605 | E3: ='202601'!Q7 -> 09001SF00000042508942193 | F3: ='202601'!F8 -> 10606.8 | G3: ='202601'!K8 -> 6057 | H3: ='202601'!L8 -> 4549.8 | I3: ='202601'!O8 -> 3231.853
A4: ='202601'!Q13 -> 0948030037341288 | B4: ='202601'!Q14 -> 0948030044194534 | C4: ='202601'!Q15 -> 09001SF00000042509164565 | D4: ='202601'!Q16 -> 0948030037341288 | E4: ='202601'!Q17 -> 09001SF00000042508942178 | F4: ='202601'!F18 -> 2864.38 | G4: ='202601'!K18 -> 948 | H4: ='202601'!L18 -> 1916.38 | I4: ='202601'!O18 -> 1376.1422
A5: ='202601'!Q23 -> 0948030028525006 | B5: ='202601'!Q24 -> 0948030044235127 | C5: ='202601'!Q25 -> 09001SF00000042508942177 | D5: ='202601'!Q26 -> 0948030028525006 | E5: ='202601'!Q27 -> 09001SF00000042508942225 | F5: ='202601'!F28 -> 7671 | G5: ='202601'!K28 -> 7591.8 | H5: ='202601'!L28 -> 79.2 | I5: ='202601'!O28 -> 55.520284
A6: ='202601'!Q33 -> 0948030030377367 | B6: ='202601'!Q34 -> 0948030044235114 | C6: ='202601'!Q35 -> 09001SF00000042508942194 | D6: ='202601'!Q36 -> 0948030030377367 | E6: ='202601'!Q37 -> 09001SF00000042508942224 | F6: ='202601'!F38 -> 9216.6 | G6: ='202601'!K38 -> 2257 | H6: ='202601'!L38 -> 6959.6 | I6: ='202601'!O38 -> 4925.2552
A7: ='202601'!Q43 -> 0948030043388253 | B7: ='202601'!Q44 -> 0948030044266295 | C7: ='202601'!Q45 -> 09001SF00000042508942195 | D7: ='202601'!Q46 -> 0948030043388253 | E7: ='202601'!Q47 -> 09001SF00000042508942191 | F7: 9822.6 | G7: ='202601'!K48 -> 6005 | H7: ='202601'!L48 -> 3817.6 | I7: ='202601'!O48 -> 2696.2977
A8: ='202601'!Q53 -> 0948030028525149 | B8: ='202601'!Q54 -> 0948030044235101 | C8: ='202601'!Q55 -> 09001SF00000042508942196 | D8: ='202601'!Q56 -> 0948030028525149 | E8: ='202601'!Q57 -> 09001SF00000042508942190 | F8: ='202601'!F58 -> 9549.6 | G8: ='202601'!K58 -> 1341 | H8: ='202601'!L58 -> 8208.6 | I8: ='202601'!O58 -> 5765.0043
A9: ='202601'!Q63 -> 0948030043525791 | B9: ='202601'!Q64 -> 0948030044235084 | C9: ='202601'!Q65 -> 09001SF00000042508942175 | D9: ='202601'!Q66 -> 0948030043525791 | E9: ='202601'!Q67 -> 09001SF00000042508942222 | F9: ='202601'!F68 -> 16408 | G9: ='202601'!K68 -> 4889 | H9: ='202601'!L68 -> 11519 | I9: ='202601'!O68 -> 8034.6704
A10: ='202601'!Q73 -> 0948030027271562 | B10: ='202601'!Q74 -> 0948030044235097 | C10: ='202601'!Q75 -> 09001SF00000042509164566 | D10: ='202601'!Q76 -> 0948030027271562 | E10: ='202601'!Q77 -> 09001SF00000042508942223 | F10: ='202601'!F78 -> 1972.75 | G10: ='202601'!K78 -> 694.2 | H10: ='202601'!L78 -> 1278.55 | I10: ='202601'!O78 -> 900.01417
A11: ='202601'!Q83 -> 0948030027333525 | B11: ='202601'!Q84 -> 0948030045008711 | C11: ='202601'!Q85 -> 09001SF00000042508943351 | D11: ='202601'!Q86 -> 0948030027333525 | E11: ='202601'!Q87 -> 09001SF00000042508942212 | F11: ='202601'!F88 -> 8817.6 | G11: ='202601'!K88 -> 3804 | H11: ='202601'!L88 -> 5013.6 | I11: ='202601'!O88 -> 3598.3604
B12: 合计 | F12: =SUM(F3:F11) -> 76929.33 | G12: =SUM(G3:G11) -> 33587 | H12: =SUM(H3:H11) -> 43342.33 | I12: =SUM(I3:I11) -> 30583.118
A13: 华尔特工业园光伏项目发电2026年2月统计表
A18: 华尔特工业园光伏项目发电2026年3月统计表
A22: 华尔特工业园光伏项目发电2026年4月统计表
A27: 华尔特工业园光伏项目发电2026年5月统计表
A32: 华尔特工业园光伏项目发电2026年6月统计表
A37: 华尔特工业园光伏项目发电2026年7月统计表
A42: 华尔特工业园光伏项目发电2026年8月统计表
A47: 华尔特工业园光伏项目发电2026年9月统计表
A52: 华尔特工业园光伏项目发电2026年10月统计表
A57: 华尔特工业园光伏项目发电2026年11月统计表
A62: 华尔特工业园光伏项目发电2026年12月统计表

Sheet 202601
A1: 华尔特工业园光伏项目发电统计表（2026年1月）
A2: 正向数据（发电量） | G2: 反向数据（上网电量） | L2: 自发用电量/金额
A3: 类别 | B3: 上月表数 | C3: 本月表数 | D3: 电表用理 | E3: 倍率 | F3: 发电量 | G3: 上月表数 | H3: 本月表数 | I3: 电表用理 | J3: 倍率 | K3: 上网电量 | L3: 实际用电数 | M3: 原电价 | N3: 优惠后电价 | O3: 金额 | P3: 用户号 | Q3: 0948030027271605 | R3: 新建9个表
A4: 正有功尖峰 | B4: 68.92 | C4: 118.77 | D4: =C4-B4 -> 49.85 | E4: 60 | F4: =D4*E4 -> 2991 | G4: 21.12 | H4: 36.62 | I4: =H4-G4 -> 15.5 | J4: 100 | K4: =I4*J4 -> 1550 | L4: =F4-K4 -> 1441 | M4: 0.95786875 | N4: =M4-0.15 -> 0.80786875 | O4: =L4*N4 -> 1164.1389 | P4: 发电表号 | Q4: 0948030044326050
A5: 正有功峰 | B5: 66.39 | C5: 113.4 | D5: =C5-B5 -> 47.01 | E5: 60 | F5: =D5*E5 -> 2820.6 | G5: 19.01 | H5: 33.62 | I5: =H5-G5 -> 14.61 | J5: 100 | K5: =I5*J5 -> 1461 | L5: =F5-K5 -> 1359.6 | M5: 0.95786875 | N5: =M5-0.15 -> 0.80786875 | O5: =L5*N5 -> 1098.3784 | P5: 发电表资产编号 | Q5: 09001SF00000042508942176
A6: 正有功平 | B6: 119.44 | C6: 198.02 | D6: =C6-B6 -> 78.58 | E6: 60 | F6: =D6*E6 -> 4714.8 | G6: 44.46 | H6: 74.64 | I6: =H6-G6 -> 30.18 | J6: 100 | K6: =I6*J6 -> 3018 | L6: =F6-K6 -> 1696.8 | M6: 0.71406875 | N6: =M6-0.15 -> 0.56406875 | O6: =L6*N6 -> 957.11186 | P6: 上网表号 | Q6: 0948030027271605
A7: 正有功谷 | B7: 3.6 | C7: 4.95 | D7: =C7-B7 -> 1.35 | E7: 60 | F7: =D7*E7 -> 81 | G7: 1.08 | H7: 1.35 | I7: =H7-G7 -> 0.27 | J7: 100 | K7: =I7*J7 -> 27 | L7: =F7-K7 -> 54 | M7: 0.22636875 | N7: =M7 -> 0.22636875 | O7: =L7*N7 -> 12.223913 | P7: 上网表资产号 | Q7: 09001SF00000042508942193
A8: 正有功总 | B8: 258.37 | C8: 435.15 | D8: =C8-B8 -> 176.78 | E8: 60 | F8: =D8*E8 -> 10606.8 | G8: 85.67 | H8: 146.24 | I8: =H8-G8 -> 60.57 | J8: 100 | K8: =I8*J8 -> 6057 | L8: =F8-K8 -> 4549.8 | O8: =SUM(O4:O7) -> 3231.853
A9: 联系电话：18938973683 | M9: 制作： | O9: 曹贤奎
A11: 华尔特工业园光伏项目发电统计表（2026年1月）
A12: 正向数据（发电量） | G12: 反向数据（上网电量） | L12: 自发用电量/金额
A13: 类别 | B13: 上月表数 | C13: 本月表数 | D13: 电表用理 | E13: 倍率 | F13: 发电量 | G13: 上月表数 | H13: 本月表数 | I13: 电表用理 | J13: 倍率 | K13: 上网电量 | L13: 实际用电数 | M13: 原电价 | N13: 优惠后电价 | O13: 金额 | P13: 用户号 | Q13: 0948030037341288
A14: 正有功尖峰 | B14: 1082.78 | C14: 1846.27 | D14: =C14-B14 -> 763.49 | E14: 1 | F14: =D14*E14 -> 763.49 | G14: 5.51 | H14: 9.16 | I14: =H14-G14 -> 3.65 | J14: 40 | K14: =I14*J14 -> 146 | L14: =F14-K14 -> 617.49 | M14: 0.95786875 | N14: =M14-0.15 -> 0.80786875 | O14: =L14*N14 -> 498.85087 | P14: 发电表号 | Q14: 0948030044194534
A15: 正有功峰 | B15: 1079.47 | C15: 1849.74 | D15: =C15-B15 -> 770.27 | E15: 1 | F15: =D15*E15 -> 770.27 | G15: 5.81 | H15: 9.57 | I15: =H15-G15 -> 3.76 | J15: 40 | K15: =I15*J15 -> 150.4 | L15: =F15-K15 -> 619.87 | M15: 0.95786875 | N15: =M15-0.15 -> 0.80786875 | O15: =L15*N15 -> 500.7736 | P15: 发电表资产编号 | Q15: 09001SF00000042509164565
A16: 正有功平 | B16: 1983.75 | C16: 3291.94 | D16: =C16-B16 -> 1308.19 | E16: 1 | F16: =D16*E16 -> 1308.19 | G16: 30.23 | H16: 46.44 | I16: =H16-G16 -> 16.21 | J16: 40 | K16: =I16*J16 -> 648.4 | L16: =F16-K16 -> 659.79 | M16: 0.71406875 | N16: =M16-0.15 -> 0.56406875 | O16: =L16*N16 -> 372.16692 | P16: 上网表号 | Q16: 0948030037341288
A17: 正有功谷 | B17: 63.69 | C17: 86.11 | D17: =C17-B17 -> 22.42 | E17: 1 | F17: =D17*E17 -> 22.42 | G17: 1.42 | H17: 1.5 | I17: =H17-G17 -> 0.08 | J17: 40 | K17: =I17*J17 -> 3.2 | L17: =F17-K17 -> 19.22 | M17: 0.22636875 | N17: =M17 -> 0.22636875 | O17: =L17*N17 -> 4.3508074 | P17: 上网表资产号 | Q17: 09001SF00000042508942178
A18: 正有功总 | B18: 4209.69 | C18: 7074.07 | D18: =C18-B18 -> 2864.38 | E18: 1 | F18: =D18*E18 -> 2864.38 | G18: 42.99 | H18: 66.69 | I18: =H18-G18 -> 23.7 | J18: 40 | K18: =I18*J18 -> 948 | L18: =F18-K18 -> 1916.38 | O18: =SUM(O14:O17) -> 1376.1422
A19: 联系电话：18938973683 | N19: 制作： | O19: 曹贤奎
A21: 华尔特工业园光伏项目发电统计表（2026年1月）
A22: 正向数据（发电量） | G22: 反向数据（上网电量） | L22: 自发用电量/金额
A23: 类别 | B23: 上月表数 | C23: 本月表数 | D23: 电表用理 | E23: 倍率 | F23: 发电量 | G23: 上月表数 | H23: 本月表数 | I23: 电表用理 | J23: 倍率 | K23: 上网电量 | L23: 实际用电数 | M23: 原电价 | N23: 优惠后电价 | O23: 金额 | P23: 用户号 | Q23: 0948030028525006
A24: 正有功尖峰 | B24: 58.73 | C24: 97.8 | D24: =C24-B24 -> 39.07 | E24: 60 | F24: =D24*E24 -> 2344.2 | G24: 57.84 | H24: 96.45 | I24: =H24-G24 -> 38.61 | J24: 60 | K24: =I24*J24 -> 2316.6 | L24: =F24-K24 -> 27.6 | M24: 0.95786875 | N24: =M24-0.15 -> 0.80786875 | O24: =L24*N24 -> 22.297177 | P24: 发电表号 | Q24: 0948030044235127
A25: 正有功峰 | B25: 55.42 | C25: 90.53 | D25: =C25-B25 -> 35.11 | E25: 60 | F25: =D25*E25 -> 2106.6 | G25: 54.79 | H25: 89.54 | I25: =H25-G25 -> 34.75 | J25: 60 | K25: =I25*J25 -> 2085 | L25: =F25-K25 -> 21.6 | M25: 0.95786875 | N25: =M25-0.15 -> 0.80786875 | O25: =L25*N25 -> 17.449965 | P25: 发电表资产编号 | Q25: 09001SF00000042508942177
A26: 正有功平 | B26: 92 | C26: 144.91 | D26: =C26-B26 -> 52.91 | E26: 60 | F26: =D26*E26 -> 3174.6 | G26: 91.06 | H26: 143.52 | I26: =H26-G26 -> 52.46 | J26: 60 | K26: =I26*J26 -> 3147.6 | L26: =F26-K26 -> 27 | M26: 0.71406875 | N26: =M26-0.15 -> 0.56406875 | O26: =L26*N26 -> 15.229856 | P26: 上网表号 | Q26: 0948030028525006
A27: 正有功谷 | B27: 2.25 | C27: 3 | D27: =C27-B27 -> 0.75 | E27: 60 | F27: =D27*E27 -> 45 | G27: 2.15 | H27: 2.86 | I27: =H27-G27 -> 0.71 | J27: 60 | K27: =I27*J27 -> 42.6 | L27: =F27-K27 -> 2.4 | M27: 0.22636875 | N27: =M27 -> 0.22636875 | O27: =L27*N27 -> 0.543285 | P27: 上网表资产号 | Q27: 09001SF00000042508942225
A28: 正有功总 | B28: 208.41 | C28: 336.26 | D28: =C28-B28 -> 127.85 | E28: 60 | F28: =D28*E28 -> 7671 | G28: 205.86 | H28: 332.39 | I28: =H28-G28 -> 126.53 | J28: 60 | K28: =I28*J28 -> 7591.8 | L28: =F28-K28 -> 79.2 | O28: =SUM(O24:O27) -> 55.520284
A29: 联系电话：18938973683 | M29: 制作： | O29: 曹贤奎
A31: 华尔特工业园光伏项目发电统计表（2026年1月）
A32: 正向数据（发电量） | G32: 反向数据（上网电量） | L32: 自发用电量/金额
A33: 类别 | B33: 上月表数 | C33: 本月表数 | D33: 电表用理 | E33: 倍率 | F33: 发电量 | G33: 上月表数 | H33: 本月表数 | I33: 电表用理 | J33: 倍率 | K33: 上网电量 | L33: 实际用电数 | M33: 原电价 | N33: 优惠后电价 | O33: 金额 | P33: 用户号 | Q33: 0948030030377367
A34: 正有功尖峰 | B34: 65.14 | C34: 106.88 | D34: =C34-B34 -> 41.74 | E34: 60 | F34: =D34*E34 -> 2504.4 | G34: 13.56 | H34: 18.72 | I34: =H34-G34 -> 5.16 | J34: 100 | K34: =I34*J34 -> 516 | L34: =F34-K34 -> 1988.4 | M34: 0.95786875 | N34: =M34-0.15 -> 0.80786875 | O34: =L34*N34 -> 1606.3662 | P34: 发电表号 | Q34: 0948030044235114
A35: 正有功峰 | B35: 63.34 | C35: 103.75 | D35: =C35-B35 -> 40.41 | E35: 60 | F35: =D35*E35 -> 2424.6 | G35: 8.75 | H35: 11.07 | I35: =H35-G35 -> 2.32 | J35: 100 | K35: =I35*J35 -> 232 | L35: =F35-K35 -> 2192.6 | M35: 0.95786875 | N35: =M35-0.15 -> 0.80786875 | O35: =L35*N35 -> 1771.333 | P35: 发电表资产编号 | Q35: 09001SF00000042508942194
A36: 正有功平 | B36: 119.81 | C36: 190.25 | D36: =C36-B36 -> 70.44 | E36: 60 | F36: =D36*E36 -> 4226.4 | G36: 31.4 | H36: 46.47 | I36: =H36-G36 -> 15.07 | J36: 100 | K36: =I36*J36 -> 1507 | L36: =F36-K36 -> 2719.4 | M36: 0.71406875 | N36: =M36-0.15 -> 0.56406875 | O36: =L36*N36 -> 1533.9286 | P36: 上网表号 | Q36: 0948030030377367
A37: 正有功谷 | B37: 3.05 | C37: 4.07 | D37: =C37-B37 -> 1.02 | E37: 60 | F37: =D37*E37 -> 61.2 | G37: 0 | H37: 0.01 | I37: =H37-G37 -> 0.01 | J37: 100 | K37: =I37*J37 -> 1 | L37: =F37-K37 -> 60.2 | M37: 0.22636875 | N37: =M37 -> 0.22636875 | O37: =L37*N37 -> 13.627399 | P37: 上网表资产号 | Q37: 09001SF00000042508942224
A38: 正有功总 | B38: 251.36 | C38: 404.97 | D38: =C38-B38 -> 153.61 | E38: 60 | F38: =D38*E38 -> 9216.6 | G38: 53.72 | H38: 76.29 | I38: =H38-G38 -> 22.57 | J38: 100 | K38: =I38*J38 -> 2257 | L38: =F38-K38 -> 6959.6 | O38: =SUM(O34:O37) -> 4925.2552
A39: 联系电话：18938973683 | M39: 制作： | O39: 曹贤奎
A41: 华尔特工业园光伏项目发电统计表（2026年1月）
A42: 正向数据（发电量） | G42: 反向数据（上网电量） | L42: 自发用电量/金额
A43: 类别 | B43: 上月表数 | C43: 本月表数 | D43: 电表用理 | E43: 倍率 | F43: 发电量 | G43: 上月表数 | H43: 本月表数 | I43: 电表用理 | J43: 倍率 | K43: 上网电量 | L43: 实际用电数 | M43: 原电价 | N43: 优惠后电价 | O43: 金额 | P43: 用户号 | Q43: 0948030043388253
A44: 正有功尖峰 | B44: 59.56 | C44: 106.01 | D44: =C44-B44 -> 46.45 | E44: 60 | F44: =D44*E44 -> 2787 | G44: 35.58 | H44: 50.93 | I44: =H44-G44 -> 15.35 | J44: 100 | K44: =I44*J44 -> 1535 | L44: =F44-K44 -> 1252 | M44: 0.95786875 | N44: =M44-0.15 -> 0.80786875 | O44: =L44*N44 -> 1011.4517 | P44: 发电表号 | Q44: 0948030044266295
...
